2025-10-03 17:41:09,403 - src.core.job_manager - INFO - Starting job for file: test_input.xlsx
2025-10-03 17:41:09,415 - src.core.job_manager - CRITICAL - An unexpected error occurred in the job thread: Simulating a crash
Traceback (most recent call last):
  File "/app/src/core/job_manager.py", line 112, in _run
    processed_record = engine.process_record(record)
                       ^^^^^^^^^^^^^^^^^^^^^^^^^^^^^
  File "/home/jules/.pyenv/versions/3.12.11/lib/python3.12/unittest/mock.py", line 1139, in __call__
    return self._mock_call(*args, **kwargs)
           ^^^^^^^^^^^^^^^^^^^^^^^^^^^^^^^^
  File "/home/jules/.pyenv/versions/3.12.11/lib/python3.12/unittest/mock.py", line 1143, in _mock_call
    return self._execute_mock_call(*args, **kwargs)
           ^^^^^^^^^^^^^^^^^^^^^^^^^^^^^^^^^^^^^^^^
  File "/home/jules/.pyenv/versions/3.12.11/lib/python3.12/unittest/mock.py", line 1204, in _execute_mock_call
    result = effect(*args, **kwargs)
             ^^^^^^^^^^^^^^^^^^^^^^^
  File "/app/tests/test_job_manager.py", line 102, in side_effect_to_stop
    raise InterruptedError("Simulating a crash")
InterruptedError: Simulating a crash
2025-10-03 17:41:09,506 - src.core.job_manager - INFO - Starting job for file: test_input.xlsx
2025-10-03 17:41:09,539 - src.core.job_manager - INFO - Job completed successfully.
2025-10-03 17:41:09,553 - src.core.job_manager - INFO - Starting job for file: test_input.xlsx
2025-10-03 17:41:09,570 - src.core.job_manager - CRITICAL - An unexpected error occurred in the job thread: Could not write to output file 'test_input_cleaned.xlsx'. Please check file permissions and ensure the path is valid. Original error: Test permission denied
Traceback (most recent call last):
  File "/app/src/core/job_manager.py", line 258, in _write_output_file
    final_df.to_excel(self.settings.output_filepath, index=False, na_rep='')
  File "/home/jules/.pyenv/versions/3.12.11/lib/python3.12/unittest/mock.py", line 1139, in __call__
    return self._mock_call(*args, **kwargs)
           ^^^^^^^^^^^^^^^^^^^^^^^^^^^^^^^^
  File "/home/jules/.pyenv/versions/3.12.11/lib/python3.12/unittest/mock.py", line 1143, in _mock_call
    return self._execute_mock_call(*args, **kwargs)
           ^^^^^^^^^^^^^^^^^^^^^^^^^^^^^^^^^^^^^^^^
  File "/home/jules/.pyenv/versions/3.12.11/lib/python3.12/unittest/mock.py", line 1198, in _execute_mock_call
    raise effect
PermissionError: Test permission denied

During handling of the above exception, another exception occurred:

Traceback (most recent call last):
  File "/app/src/core/job_manager.py", line 139, in _run
    self._write_output_file()
  File "/app/src/core/job_manager.py", line 261, in _write_output_file
    raise IOError(f"Could not write to output file '{self.settings.output_filepath}'. "
OSError: Could not write to output file 'test_input_cleaned.xlsx'. Please check file permissions and ensure the path is valid. Original error: Test permission denied
2025-10-03 17:41:09,584 - src.core.job_manager - INFO - Starting job for file: test_input.xlsx
2025-10-03 17:41:09,616 - src.core.job_manager - INFO - Job completed successfully.
2025-10-03 17:41:09,628 - src.core.job_manager - INFO - Starting job for file: test_input.xlsx
2025-10-03 17:41:09,638 - src.core.job_manager - CRITICAL - An unexpected error occurred in the job thread: A random backend error occurred
Traceback (most recent call last):
  File "/app/src/core/job_manager.py", line 112, in _run
    processed_record = engine.process_record(record)
                       ^^^^^^^^^^^^^^^^^^^^^^^^^^^^^
  File "/home/jules/.pyenv/versions/3.12.11/lib/python3.12/unittest/mock.py", line 1139, in __call__
    return self._mock_call(*args, **kwargs)
           ^^^^^^^^^^^^^^^^^^^^^^^^^^^^^^^^
  File "/home/jules/.pyenv/versions/3.12.11/lib/python3.12/unittest/mock.py", line 1143, in _mock_call
    return self._execute_mock_call(*args, **kwargs)
           ^^^^^^^^^^^^^^^^^^^^^^^^^^^^^^^^^^^^^^^^
  File "/home/jules/.pyenv/versions/3.12.11/lib/python3.12/unittest/mock.py", line 1198, in _execute_mock_call
    raise effect
Exception: A random backend error occurred
